<?xml version="1.0" ?>
<!-- =================================================================================== -->
<!-- |    This document was autogenerated by xacro from robot.xacro                    | -->
<!-- |    EDITING THIS FILE BY HAND IS NOT RECOMMENDED                                 | -->
<!-- =================================================================================== -->
<robot name="soar" xmlns:controller="http://playerstage.sourceforge.net/gazebo/xmlschema/#controller" xmlns:interface="http://playerstage.sourceforge.net/gazebo/xmlschema/#interface" xmlns:sensor="http://playerstage.sourceforge.net/gazebo/xmlschema/#sensor">
  <!-- base -->
  <link name="base_footprint"/>
  <joint name="base_joint" type="fixed">
    <parent link="base_footprint"/>
    <child link="base_link"/>
    <origin rpy="0.0 0.0 0.0" xyz="0.0 0.0 0.0"/>
  </joint>
  <link name="base_link">
    <visual>
      <origin rpy="0 0 0" xyz="0 0 0"/>
      <geometry>
        <mesh filename="meshes/base_link_combined.stl"/>
      </geometry>
      <material name="white">
        <color rgba="1 1 1 1"/>
      </material>
    </visual>
    <collision>
      <origin rpy="0 0 0" xyz="0.015 0 0.2295"/>
      <geometry>
        <box size="0.67 0.21539106 0.409"/>
      </geometry>
    </collision>
    <collision>
      <origin rpy="0 0 0" xyz="0.015 0 0.2295"/>
      <geometry>
        <box size="0.49426406 0.52 0.409"/>
      </geometry>
    </collision>
    <collision>
      <origin rpy="0 0 0.5232783221319756" xyz="0.2 0.12265583 0.2295"/>
      <geometry>
        <box size="0.24490367627066678 0.1758335352563228 0.409"/>
      </geometry>
    </collision>
    <collision>
      <origin rpy="0 0 -0.5232783221319756" xyz="0.2 -0.12265583 0.2295"/>
      <geometry>
        <box size="0.24490367627066678 0.1758335352563228 0.409"/>
      </geometry>
    </collision>
    <collision>
      <origin rpy="0 0 2.6183143314578174" xyz="-0.17 0.12265583 0.2295"/>
      <geometry>
        <box size="0.24490367627066678 0.1758335352563228 0.409"/>
      </geometry>
    </collision>
    <collision>
      <origin rpy="0 0 3.664870975721769" xyz="-0.17 -0.12265583 0.2295"/>
      <geometry>
        <box size="0.24490367627066678 0.1758335352563228 0.409"/>
      </geometry>
    </collision>
    <!-- inner cover -->
    <collision>
      <origin rpy="0 0 0" xyz="-0.172 0 0.657"/>
      <geometry>
        <box size="0.238 0.342 0.460"/>
      </geometry>
    </collision>
    <inertial>
      <origin rpy="0 0 0" xyz="0.015 0 0.217"/>
      <mass value="45"/>
      <inertia ixx="1.7203350000000002" ixy="0.0" ixz="0.0" iyy="2.3897100000000004" iyz="0.0" izz="2.6973750000000005"/>
    </inertial>
  </link>
  <gazebo reference="base_link">
    <kp>1000000.0</kp>
    <kd>1000000.0</kd>
    <mu1>100000</mu1>
    <mu2>100000</mu2>
    <maxVel>0.0</maxVel>
    <minDepth>0.0</minDepth>
    <maxContacts>5</maxContacts>
    <dampingFactor>0.0</dampingFactor>
  </gazebo>
  <joint name="wheel_left_joint" type="continuous">
    <parent link="base_link"/>
    <child link="wheel_left"/>
    <origin rpy="0 0 0" xyz="0 0.23 0.075"/>
    <axis xyz="0 1 0"/>
    <limit effort="100000.0" velocity="100.0"/>
  </joint>
  <transmission name="wheel_left_transmission">
    <type>transmission_interface/SimpleTransmission</type>
    <joint name="wheel_left_joint">
      <hardwareInterface>hardware_interface/VelocityJointInterface</hardwareInterface>
    </joint>
    <actuator name="wheel_left_motor">
      <mechanicalReduction>1</mechanicalReduction>
    </actuator>
  </transmission>
  <link name="wheel_left">
    <visual>
      <origin rpy="1.5707963267948966 0 0" xyz="0 0 0"/>
      <geometry>
        <cylinder length="0.032" radius="0.075"/>
      </geometry>
      <material name="blue">
        <color rgba="0 0 0.8 1"/>
      </material>
    </visual>
    <collision>
      <origin rpy="1.5707963267948966 0 0" xyz="0 0 0"/>
      <geometry>
        <cylinder length="0.032" radius="0.075"/>
      </geometry>
    </collision>
    <inertial>
      <mass value="50"/>
      <origin xyz="0 0 0"/>
      <inertia ixx="0.1" ixy="0.0" ixz="0.0" iyy="0.1" iyz="0.0" izz="0.1"/>
    </inertial>
  </link>
  <gazebo reference="wheel_left">
    <material>Gazebo/Blue</material>
    <mu1>100000</mu1>
    <mu2>100000</mu2>
    <kp>400000.0</kp>
    <kd>400000.0</kd>
    <minDepth>0.0</minDepth>
    <maxContacts>5</maxContacts>
    <selfCollide>false</selfCollide>
    <dampingFactor>0.0</dampingFactor>
  </gazebo>
  <joint name="wheel_right_joint" type="continuous">
    <parent link="base_link"/>
    <child link="wheel_right"/>
    <origin rpy="0 0 0" xyz="0 -0.23 0.075"/>
    <axis xyz="0 1 0"/>
    <limit effort="100000.0" velocity="100.0"/>
  </joint>
  <transmission name="wheel_right_transmission">
    <type>transmission_interface/SimpleTransmission</type>
    <joint name="wheel_right_joint">
      <hardwareInterface>hardware_interface/VelocityJointInterface</hardwareInterface>
    </joint>
    <actuator name="wheel_right_motor">
      <mechanicalReduction>1</mechanicalReduction>
    </actuator>
  </transmission>
  <link name="wheel_right">
    <visual>
      <origin rpy="1.5707963267948966 0 0" xyz="0 0 0"/>
      <geometry>
        <cylinder length="0.032" radius="0.075"/>
      </geometry>
      <material name="blue">
        <color rgba="0 0 0.8 1"/>
      </material>
    </visual>
    <collision>
      <origin rpy="1.5707963267948966 0 0" xyz="0 0 0"/>
      <geometry>
        <cylinder length="0.032" radius="0.075"/>
      </geometry>
    </collision>
    <inertial>
      <mass value="50"/>
      <origin xyz="0 0 0"/>
      <inertia ixx="0.1" ixy="0.0" ixz="0.0" iyy="0.1" iyz="0.0" izz="0.1"/>
    </inertial>
  </link>
  <gazebo reference="wheel_right">
    <material>Gazebo/Blue</material>
    <mu1>100000</mu1>
    <mu2>100000</mu2>
    <kp>400000.0</kp>
    <kd>400000.0</kd>
    <minDepth>0.0</minDepth>
    <maxContacts>5</maxContacts>
    <selfCollide>false</selfCollide>
    <dampingFactor>0.0</dampingFactor>
  </gazebo>
  <joint name="laser_joint" type="fixed">
    <axis xyz="0 1 0"/>
    <origin rpy="0 0 0" xyz="0.1375 0.0 0.3715"/>
    <parent link="base_link"/>
    <child link="laser_link"/>
  </joint>
  <link name="laser_link">
    <inertial>
      <origin rpy="0 0 0" xyz="0 0 -0.015"/>
      <mass value="0.001"/>
      <inertia ixx="0.00000002" ixy="0" ixz="0" iyy="0.00000002" iyz="0" izz="0.00000002"/>
    </inertial>
    <visual>
      <origin rpy="0 0 0" xyz="0 0 -0.015"/>
      <geometry>
        <cylinder length="0.09" radius="0.043"/>
      </geometry>
    </visual>
    <collision>
      <origin rpy="0 0 0" xyz="0 0 -0.015"/>
      <geometry>
        <cylinder length="0.09" radius="0.043"/>
      </geometry>
    </collision>
  </link>
  <gazebo reference="laser_link">
    <material>Gazebo/Red</material>
    <sensor name="laser" type="gpu_ray">
      <update_rate>30</update_rate>
      <pose>0 0 0 0 0 0</pose>
      <visualize>false</visualize>
      <ray>
        <scan>
          <horizontal>
            <samples>6666</samples>
            <resolution>1</resolution>
            <min_angle>0</min_angle>
            <max_angle>6.283185307179586</max_angle>
          </horizontal>
        </scan>
        <range>
          <min>0.1</min>
          <max>50.0</max>
          <resolution>0.01</resolution>
        </range>
        <noise>
          <type>gaussian</type>
          <mean>0.0</mean>
          <stddev>0.004</stddev>
        </noise>
      </ray>
      <plugin filename="libgazebo_ros_gpu_laser.so" name="laser_controller">
        <topicName>laser/scan</topicName>
        <frameName>laser_link</frameName>
      </plugin>
    </sensor>
  </gazebo>
  <joint name="imu_joint" type="fixed">
    <parent link="base_link"/>
    <child link="imu_link"/>
    <origin rpy="0 0 0" xyz="0 0 0.367"/>
  </joint>
  <link name="imu_link">
    <visual>
      <origin rpy="0 0 0" xyz="0 0 0"/>
      <geometry>
        <box size="0.05 0.05 0.01"/>
      </geometry>
      <material name="gray">
        <color rgba="0.5 0.5 0.5 1"/>
      </material>
    </visual>
    <collision>
      <origin rpy="0 0 0" xyz="0 0 0"/>
      <geometry>
        <box size="0.05 0.05 0.01"/>
      </geometry>
    </collision>
    <inertial>
      <origin rpy="0 0 0" xyz="0 0 0"/>
      <mass value="0.001"/>
      <inertia ixx="0.00000002" ixy="0" ixz="0" iyy="0.00000002" iyz="0" izz="0.00000002"/>
    </inertial>
  </link>
  <gazebo reference="imu_link">
    <material>Gazebo/Gray</material>
  </gazebo>
  <gazebo>
    <plugin filename="libhector_gazebo_ros_imu.so" name="imu_controller">
      <alwaysOn>true</alwaysOn>
      <updateRate>100</updateRate>
      <bodyName>imu_link</bodyName>
      <topicName>imu/data</topicName>
      <serviceName>imu/service</serviceName>
      <frameId>imu_link</frameId>
      <gaussianNoise>0</gaussianNoise>
      <xyzOffset>0 0 0</xyzOffset>
      <rateOffset>0 0 0.01</rateOffset>
      <rpyOffset>0 0 0</rpyOffset>
    </plugin>
    <plugin filename="libhector_gazebo_ros_magnetic.so" name="magnetic_controller">
      <alwaysOn>true</alwaysOn>
      <updateRate>100</updateRate>
      <bodyName>imu_link</bodyName>
      <topicName>imu/mag</topicName>
      <frameId>imu_link</frameId>
      <useMagneticFieldMsgs>true</useMagneticFieldMsgs>
      <magnitude>0.000047</magnitude>
      <declination>-7.81</declination>
      <inclination>49.48</inclination>
      <offset>0 0 0</offset>
      <drift>0 0 0</drift>
      <driftFrequency>0 0 0</driftFrequency>
      <gaussianNoise>0 0 0</gaussianNoise>
    </plugin>
  </gazebo>
  <!-- plate -->
  <joint name="plate_joint" type="fixed">
    <parent link="base_link"/>
    <child link="plate_link"/>
    <origin rpy="0.0 0.0 0.0" xyz="0.1656755 0.0 0.427"/>
  </joint>
  <link name="plate_link">
    <collision>
      <origin rpy="0 0 0" xyz="0.015 0 -0.0115"/>
      <geometry>
        <box size="0.17735101 0.38023799 0.037"/>
      </geometry>
    </collision>
  </link>
  <gazebo reference="plate_link">
    <kp>1000000.0</kp>
    <kd>1000000.0</kd>
    <mu1>100000</mu1>
    <mu2>100000</mu2>
    <maxVel>0.0</maxVel>
    <minDepth>0.0</minDepth>
    <maxContacts>5</maxContacts>
    <dampingFactor>0.0</dampingFactor>
  </gazebo>
  <joint name="front_caster_joint" type="fixed">
    <origin rpy="0.0 0.0 0.0" xyz="0.2425 0.0 0.0625"/>
    <parent link="base_link"/>
    <child link="front_caster_link"/>
  </joint>
  <link name="front_caster_link">
    <visual>
      <origin rpy="1.5707963267948966 0 0" xyz="0 0 0"/>
      <geometry>
        <cylinder length="0.035" radius="0.0625"/>
      </geometry>
      <material name="Black">
        <color rgba="0.0 0.0 0.0 1.0"/>
      </material>
    </visual>
    <collision>
      <origin rpy="1.5707963267948966 0 0" xyz="0 0 0"/>
      <geometry>
        <sphere radius="0.0625"/>
      </geometry>
    </collision>
    <inertial>
      <origin rpy="1.5707963267948966 0 0" xyz="0 0 0"/>
      <mass value="0.5"/>
      <inertia ixx="0.0005393229166666667" ixy="0.0" ixz="0.0" iyy="0.0005393229166666667" iyz="0.0" izz="0.0009765625"/>
    </inertial>
  </link>
  <gazebo reference="front_caster_link">
    <material>Gazebo/Black</material>
    <kp>1000000.0</kp>
    <kd>1000000.0</kd>
    <mu1>0.0</mu1>
    <mu2>0.0</mu2>
    <minDepth>0.0</minDepth>
    <maxContacts>5</maxContacts>
    <dampingFactor>0.0</dampingFactor>
    <selfCollide>false</selfCollide>
  </gazebo>
  <joint name="rear_caster_joint" type="fixed">
    <origin rpy="0.0 0.0 0.0" xyz="-0.2425 0.0 0.0625"/>
    <parent link="base_link"/>
    <child link="rear_caster_link"/>
  </joint>
  <link name="rear_caster_link">
    <visual>
      <origin rpy="1.5707963267948966 0 0" xyz="0 0 0"/>
      <geometry>
        <cylinder length="0.035" radius="0.0625"/>
      </geometry>
      <material name="Black">
        <color rgba="0.0 0.0 0.0 1.0"/>
      </material>
    </visual>
    <collision>
      <origin rpy="1.5707963267948966 0 0" xyz="0 0 0"/>
      <geometry>
        <sphere radius="0.0625"/>
      </geometry>
    </collision>
    <inertial>
      <origin rpy="1.5707963267948966 0 0" xyz="0 0 0"/>
      <mass value="0.5"/>
      <inertia ixx="0.0005393229166666667" ixy="0.0" ixz="0.0" iyy="0.0005393229166666667" iyz="0.0" izz="0.0009765625"/>
    </inertial>
  </link>
  <gazebo reference="rear_caster_link">
    <material>Gazebo/Black</material>
    <kp>1000000.0</kp>
    <kd>1000000.0</kd>
    <mu1>0.0</mu1>
    <mu2>0.0</mu2>
    <minDepth>0.0</minDepth>
    <maxContacts>5</maxContacts>
    <dampingFactor>0.0</dampingFactor>
    <selfCollide>false</selfCollide>
  </gazebo>
  <material name="aluminum">
    <color rgba="0.5 0.5 0.5 1"/>
  </material>
  <material name="plastic">
    <color rgba="0.1 0.1 0.1 1"/>
  </material>
  <gazebo>
    <plugin filename="libgazebo_ros_control.so" name="gazebo_ros_control">
      <robotNamespace>/soar</robotNamespace>
      <robotSimType>gazebo_ros_control/DefaultRobotHWSim</robotSimType>
      <legacyModeNS>false</legacyModeNS>
    </plugin>
  </gazebo>
  <joint name="torso_joint" type="prismatic">
    <origin rpy="0 0 0" xyz="-0.099 0.0 0.547"/>
    <parent link="base_link"/>
    <child link="torso_link"/>
    <axis xyz="0 0 1"/>
    <limit effort="5000.0" lower="0.0" upper="0.41" velocity="0.1"/>
    <!-- <safety_controller k_velocity="200" soft_lower_limit="${-0.420+0.005}" soft_upper_limit="${0.0005-0.005}" k_position="100"/> -->
    <!--<dynamics damping="0.01" friction="1.0"/>-->
  </joint>
  <transmission name="torso_transmission">
    <type>transmission_interface/SimpleTransmission</type>
    <joint name="torso_joint">
      <hardwareInterface>hardware_interface/PositionJointInterface</hardwareInterface>
    </joint>
    <actuator name="torso_motor">
      <mechanicalReduction>1</mechanicalReduction>
    </actuator>
  </transmission>
  <link name="torso_link">
    <visual>
      <origin rpy="0 0 0" xyz="0 0 0"/>
      <geometry>
        <mesh filename="meshes/torso.stl"/>
      </geometry>
      <material name="white">
        <color rgba="1 1 1 1"/>
      </material>
    </visual>
    <collision>
      <origin rpy="0 0 0" xyz="0 0 0"/>
      <geometry>
        <mesh filename="meshes/torso.stl"/>
      </geometry>
    </collision>
    <inertial>
      <origin rpy="0 0 0" xyz="-0.005983442068099976 0 0.2835000120103359"/>
      <mass value="2.0"/>
      <inertia ixx="0.12447683333333336" ixy="0.0" ixz="0.0" iyy="0.12727514551483335" iyz="0.0" izz="0.04843164551483333"/>
    </inertial>
  </link>
  <gazebo reference="torso_link">
    <kp>10000.0</kp>
    <kd>0.0</kd>
    <mu1>0.0</mu1>
    <mu2>0.0</mu2>
    <maxVel>0.1</maxVel>
    <minDepth>0.0001</minDepth>
    <maxContacts>0</maxContacts>
    <selfCollide>false</selfCollide>
  </gazebo>
  <!--
  Author: Jimy Zhang <jimy.zhang@ufactory.cc> <jimy92@163.com>
  Contributers:
-->
  <joint name="arm_world_joint" type="fixed">
    <parent link="torso_link"/>
    <child link="arm_link_base"/>
    <origin rpy="0 0 -0.5235987755982988" xyz="0.102 0 0"/>
  </joint>
  <material name="Black">
    <color rgba="0.0 0.0 0.0 1.0"/>
  </material>
  <material name="Red">
    <color rgba="0.8 0.0 0.0 1.0"/>
  </material>
  <material name="White">
    <color rgba="1.0 1.0 1.0 1.0"/>
  </material>
  <material name="Silver">
    <color rgba="0.753 0.753 0.753 1.0"/>
  </material>
  <link name="arm_link_base">
    <inertial>
      <origin rpy="0 0 0" xyz="-0.021131 -0.0016302 0.056488"/>
      <mass value="0.88556"/>
      <inertia ixx="0.0030595" ixy="0.00012259" ixz="-0.00062705" iyy="0.0037783" iyz="0.00027023" izz="0.0020125"/>
    </inertial>
    <visual>
      <origin rpy="0 0 0" xyz="0 0 0"/>
      <geometry>
        <mesh filename="meshes/xarm7/collision/link_base.STL"/>
      </geometry>
      <material name="White"/>
    </visual>
    <collision>
      <origin rpy="0 0 0" xyz="0 0 0"/>
      <geometry>
        <mesh filename="meshes/xarm7/collision/link_base.STL"/>
      </geometry>
    </collision>
  </link>
  <link name="arm_link1">
    <inertial>
      <origin rpy="0 0 0" xyz="-0.0042 0.0282 0.1032"/>
      <mass value="0.42603"/>
      <inertia ixx="0.0014243" ixy="3.9946E-05" ixz="4.7078E-06" iyy="0.00123" iyz="-0.00026073" izz="0.00099229"/>
    </inertial>
    <visual>
      <origin rpy="0 0 0" xyz="0 0 0.112"/>
      <geometry>
        <mesh filename="meshes/xarm7/collision/link1.STL"/>
      </geometry>
      <material name="White"/>
    </visual>
    <collision>
      <origin rpy="0 0 0" xyz="0 0 0.112"/>
      <geometry>
        <mesh filename="meshes/xarm7/collision/link1.STL"/>
      </geometry>
    </collision>
  </link>
  <joint name="arm_joint1" type="revolute">
    <origin rpy="0 0 0" xyz="0 0 0.155"/>
    <parent link="arm_link_base"/>
    <child link="arm_link1"/>
    <axis xyz="0 0 1"/>
    <limit effort="42" lower="-2.6" upper="0.506" velocity="2.826"/>
    <dynamics damping="1.0" friction="0"/>
  </joint>
  <link name="arm_link2">
    <inertial>
      <origin rpy="0 0 0" xyz="0 -0.1285 -0.0487"/>
      <mass value="0.56095"/>
      <inertia ixx="0.0031915" ixy="3.0892E-06" ixz="2.8729E-06" iyy="0.0017468" iyz="-0.0010241" izz="0.00235"/>
    </inertial>
    <visual>
      <origin rpy="0 0 0" xyz="0 0 -0.075"/>
      <geometry>
        <mesh filename="meshes/xarm7/collision/link2.STL"/>
      </geometry>
      <material name="White"/>
    </visual>
    <collision>
      <origin rpy="0 0 0" xyz="0 0 -0.075"/>
      <geometry>
        <mesh filename="meshes/xarm7/collision/link2.STL"/>
      </geometry>
    </collision>
  </link>
  <joint name="arm_joint2" type="revolute">
    <origin rpy="-1.5708 0 0" xyz="0 0.075 0.112"/>
    <parent link="arm_link1"/>
    <child link="arm_link2"/>
    <axis xyz="0 0 1"/>
    <limit effort="42" lower="-2.059" upper="2.0944" velocity="2.826"/>
    <dynamics damping="1.0" friction="0"/>
  </joint>
  <link name="arm_link3">
    <inertial>
      <origin rpy="0 0 0" xyz="0.0422 -0.0233 0.0913"/>
      <mass value="0.44463"/>
      <inertia ixx="0.0011454" ixy="0.0001654" ixz="-0.0001951" iyy="0.0010503" iyz="0.00012027" izz="0.0011083"/>
    </inertial>
    <visual>
      <origin rpy="0 0 0" xyz="0 0 0.101"/>
      <geometry>
        <mesh filename="meshes/xarm7/collision/link3.STL"/>
      </geometry>
      <material name="White"/>
    </visual>
    <collision>
      <origin rpy="0 0 0" xyz="0 0 0.101"/>
      <geometry>
        <mesh filename="meshes/xarm7/collision/link3.STL"/>
      </geometry>
    </collision>
  </link>
  <joint name="arm_joint3" type="revolute">
    <origin rpy="1.5708 0 0" xyz="0 -0.192 -0.075"/>
    <parent link="arm_link2"/>
    <child link="arm_link3"/>
    <axis xyz="0 0 1"/>
    <limit effort="19" lower="-3.141" upper="3.141" velocity="2.86"/>
    <dynamics damping="1.0" friction="0"/>
  </joint>
  <link name="arm_link4">
    <inertial>
      <origin rpy="0 0 0" xyz="0.0671 -0.1073 -0.0425"/>
      <mass value="0.52387"/>
      <inertia ixx="0.0026033" ixy="0.00053379" ixz="0.00036314" iyy="0.0017649" iyz="-0.00083253" izz="0.0022431"/>
    </inertial>
    <visual>
      <origin rpy="0 0 0" xyz="0 0 -0.067"/>
      <geometry>
        <mesh filename="meshes/xarm7/collision/link4.STL"/>
      </geometry>
      <material name="White"/>
    </visual>
    <collision>
      <origin rpy="0 0 0" xyz="0 0 -0.067"/>
      <geometry>
        <mesh filename="meshes/xarm7/collision/link4.STL"/>
      </geometry>
    </collision>
  </link>
  <joint name="arm_joint4" type="revolute">
    <origin rpy="1.5708 0 0" xyz="0.0525 -0.067 0.101"/>
    <parent link="arm_link3"/>
    <child link="arm_link4"/>
    <axis xyz="0 0 1"/>
    <limit effort="19" lower="-0.19198" upper="3.927" velocity="2.826"/>
    <dynamics damping="1.0" friction="0"/>
  </joint>
  <link name="arm_link5">
    <inertial>
      <origin rpy="0 0 0" xyz="-0.0002 0.0367 0.0929"/>
      <mass value="0.18554"/>
      <inertia ixx="0.00099549" ixy="8.9957E-07" ixz="8.5285E-07" iyy="0.0008853" iyz="-0.00025682" izz="0.00035048"/>
    </inertial>
    <visual>
      <origin rpy="0 0 0" xyz="0 0 0.173"/>
      <geometry>
        <mesh filename="meshes/xarm7/collision/link5.STL"/>
      </geometry>
      <material name="White"/>
    </visual>
    <collision>
      <origin rpy="0 0 0" xyz="0 0 0.173"/>
      <geometry>
        <mesh filename="meshes/xarm7/collision/link5.STL"/>
      </geometry>
    </collision>
  </link>
  <joint name="arm_joint5" type="revolute">
    <origin rpy="1.5708 0 0" xyz="0.0775 -0.169 -0.067"/>
    <parent link="arm_link4"/>
    <child link="arm_link5"/>
    <axis xyz="0 0 1"/>
    <limit effort="19" lower="-3.141" upper="3.141" velocity="2.826"/>
    <dynamics damping="1.0" friction="0"/>
  </joint>
  <link name="arm_link6">
    <inertial>
      <origin rpy="0 0 0" xyz="0.058911 0.028469 0.0068428"/>
      <mass value="0.31344"/>
      <inertia ixx="0.00052034" ixy="-0.00014989" ixz="0.00011658" iyy="0.00067968" iyz="6.116E-05" izz="0.00078345"/>
    </inertial>
    <visual>
      <origin rpy="0 0 0" xyz="0 0 0"/>
      <geometry>
        <mesh filename="meshes/xarm7/collision/link6.STL"/>
      </geometry>
      <material name="White"/>
    </visual>
    <collision>
      <origin rpy="0 0 0" xyz="0 0 0"/>
      <geometry>
        <mesh filename="meshes/xarm7/collision/link6.STL"/>
      </geometry>
    </collision>
  </link>
  <joint name="arm_joint6" type="revolute">
    <origin rpy="1.5708 0 0" xyz="0 0 0.173"/>
    <parent link="arm_link5"/>
    <child link="arm_link6"/>
    <axis xyz="0 0 1"/>
    <limit effort="7" lower="-1.57" upper="3.141592653589793" velocity="2.826"/>
    <dynamics damping="1.0" friction="0"/>
  </joint>
  <link name="arm_link7">
    <inertial>
      <origin rpy="0 0 0" xyz="0 -0.0046 0.0153"/>
      <mass value="0.31468"/>
      <inertia ixx="0.00016985" ixy="1.1102E-07" ixz="5.1075E-08" iyy="0.00011924" iyz="-2.1251E-06" izz="0.00026032"/>
    </inertial>
    <visual>
      <origin rpy="0 0 0" xyz="0 0 0.028"/>
      <geometry>
        <mesh filename="meshes/xarm7/collision/link7.STL"/>
      </geometry>
      <material name="Silver"/>
    </visual>
    <collision>
      <origin rpy="0 0 0" xyz="0 0 0.028"/>
      <geometry>
        <mesh filename="meshes/xarm7/collision/link7.STL"/>
      </geometry>
    </collision>
  </link>
  <joint name="arm_joint7" type="revolute">
    <origin rpy="-1.5708 0 0" xyz="0.076 0.069 0"/>
    <parent link="arm_link6"/>
    <child link="arm_link7"/>
    <axis xyz="0 0 1"/>
    <limit effort="7" lower="-3.141" upper="3.141" velocity="2.826"/>
    <dynamics damping="1.0" friction="0"/>
  </joint>
  <link name="arm_link_eef"/>
  <joint name="arm_joint_eef" type="fixed">
    <origin rpy="0 0 0" xyz="0 0 0.028"/>
    <parent link="arm_link7"/>
    <child link="arm_link_eef"/>
  </joint>
  <transmission name="arm_tran1">
    <type>transmission_interface/SimpleTransmission</type>
    <joint name="arm_joint1">
      <hardwareInterface>hardware_interface/PositionJointInterface</hardwareInterface>
    </joint>
    <actuator name="arm_motor1">
      <hardwareInterface>hardware_interface/PositionJointInterface</hardwareInterface>
      <mechanicalReduction>100</mechanicalReduction>
    </actuator>
  </transmission>
  <transmission name="arm_tran2">
    <type>transmission_interface/SimpleTransmission</type>
    <joint name="arm_joint2">
      <hardwareInterface>hardware_interface/PositionJointInterface</hardwareInterface>
    </joint>
    <actuator name="arm_motor2">
      <hardwareInterface>hardware_interface/PositionJointInterface</hardwareInterface>
      <mechanicalReduction>100</mechanicalReduction>
    </actuator>
  </transmission>
  <transmission name="arm_tran3">
    <type>transmission_interface/SimpleTransmission</type>
    <joint name="arm_joint3">
      <hardwareInterface>hardware_interface/PositionJointInterface</hardwareInterface>
    </joint>
    <actuator name="arm_motor3">
      <hardwareInterface>hardware_interface/PositionJointInterface</hardwareInterface>
      <mechanicalReduction>100</mechanicalReduction>
    </actuator>
  </transmission>
  <transmission name="arm_tran4">
    <type>transmission_interface/SimpleTransmission</type>
    <joint name="arm_joint4">
      <hardwareInterface>hardware_interface/PositionJointInterface</hardwareInterface>
    </joint>
    <actuator name="arm_motor3">
      <hardwareInterface>hardware_interface/PositionJointInterface</hardwareInterface>
      <mechanicalReduction>100</mechanicalReduction>
    </actuator>
  </transmission>
  <transmission name="arm_tran5">
    <type>transmission_interface/SimpleTransmission</type>
    <joint name="arm_joint5">
      <hardwareInterface>hardware_interface/PositionJointInterface</hardwareInterface>
    </joint>
    <actuator name="arm_motor5">
      <hardwareInterface>hardware_interface/PositionJointInterface</hardwareInterface>
      <mechanicalReduction>100</mechanicalReduction>
    </actuator>
  </transmission>
  <transmission name="arm_tran6">
    <type>transmission_interface/SimpleTransmission</type>
    <joint name="arm_joint6">
      <hardwareInterface>hardware_interface/PositionJointInterface</hardwareInterface>
    </joint>
    <actuator name="arm_motor6">
      <hardwareInterface>hardware_interface/PositionJointInterface</hardwareInterface>
      <mechanicalReduction>100</mechanicalReduction>
    </actuator>
  </transmission>
  <transmission name="arm_tran7">
    <type>transmission_interface/SimpleTransmission</type>
    <joint name="arm_joint7">
      <hardwareInterface>hardware_interface/PositionJointInterface</hardwareInterface>
    </joint>
    <actuator name="arm_motor7">
      <hardwareInterface>hardware_interface/PositionJointInterface</hardwareInterface>
      <mechanicalReduction>100</mechanicalReduction>
    </actuator>
  </transmission>
  <gazebo reference="arm_link_base">
    <selfCollide>false</selfCollide>
  </gazebo>
  <gazebo reference="arm_link1">
    <selfCollide>false</selfCollide>
  </gazebo>
  <gazebo reference="arm_link2">
    <selfCollide>false</selfCollide>
  </gazebo>
  <gazebo reference="arm_link3">
    <selfCollide>false</selfCollide>
  </gazebo>
  <gazebo reference="arm_link4">
    <selfCollide>false</selfCollide>
  </gazebo>
  <gazebo reference="arm_link5">
    <selfCollide>false</selfCollide>
  </gazebo>
  <gazebo reference="arm_link6">
    <selfCollide>false</selfCollide>
  </gazebo>
  <gazebo reference="arm_link7">
    <selfCollide>false</selfCollide>
  </gazebo>
  <gazebo reference="arm_joint1">
    <implicitSpringDamper>1</implicitSpringDamper>
  </gazebo>
  <gazebo reference="arm_joint2">
    <implicitSpringDamper>1</implicitSpringDamper>
  </gazebo>
  <gazebo reference="arm_joint3">
    <implicitSpringDamper>1</implicitSpringDamper>
  </gazebo>
  <gazebo reference="arm_joint4">
    <implicitSpringDamper>1</implicitSpringDamper>
  </gazebo>
  <gazebo reference="arm_joint5">
    <implicitSpringDamper>1</implicitSpringDamper>
  </gazebo>
  <gazebo reference="arm_joint6">
    <implicitSpringDamper>1</implicitSpringDamper>
  </gazebo>
  <gazebo reference="arm_joint7">
    <implicitSpringDamper>1</implicitSpringDamper>
  </gazebo>
  <!-- gazebo plugin -->
  <!-- <xacro:gazebo_ros_control_plugin namespace="${ns}"/> -->
  <joint name="gripper_fix" type="fixed">
    <parent link="arm_link_eef"/>
    <child link="xarm_gripper_base_link"/>
    <origin rpy="0 0 0" xyz="0 0 0.0015"/>
  </joint>
  <link name="xarm_gripper_base_link">
    <inertial>
      <origin rpy="0 0 0" xyz="-0.00065489 -0.0018497 0.048028"/>
      <mass value="0.54156"/>
      <inertia ixx="0.00047106" ixy="3.9292E-07" ixz="2.6537E-06" iyy="0.00033072" iyz="-1.0975E-05" izz="0.00025642"/>
    </inertial>
    <visual>
      <origin rpy="0 0 0" xyz="0 0 0"/>
      <geometry>
        <mesh filename="meshes/xarm_gripper_base_link_combined.stl"/>
      </geometry>
      <!-- <material
        name="">
        <color
          rgba="0.89804 0.91765 0.92941 1" />
      </material> -->
      <material name="White">
        <color rgba="1.0 1.0 1.0 1.0"/>
      </material>
    </visual>
    <collision>
      <origin rpy="0 0 0" xyz="-0.0015 0 0.055"/>
      <geometry>
        <box size="0.053 0.1 0.1"/>
      </geometry>
    </collision>
    <collision>
      <origin rpy="0 0 0" xyz="0.03 -0.062 0.025"/>
      <geometry>
        <box size="0.076 0.024 0.04"/>
      </geometry>
    </collision>
  </link>
  <link name="left_outer_knuckle">
    <inertial>
      <origin rpy="0 0 0" xyz="2.9948E-14 0.021559 0.015181"/>
      <mass value="0.033618"/>
      <inertia ixx="1.9111E-05" ixy="-1.8803E-17" ixz="-1.1002E-17" iyy="6.6256E-06" iyz="-7.3008E-06" izz="1.3185E-05"/>
    </inertial>
    <visual>
      <origin rpy="0 0 0" xyz="0 0 0"/>
      <geometry>
        <mesh filename="meshes/xarm_gripper/left_outer_knuckle.STL"/>
      </geometry>
      <material name="Silver">
        <color rgba="0.753 0.753 0.753 1.0"/>
      </material>
    </visual>
    <collision>
      <origin rpy="0.48 0 0" xyz="0 0.015 0.02"/>
      <geometry>
        <box size="0.012 0.069 0.033"/>
      </geometry>
    </collision>
  </link>
  <joint name="drive_joint" type="revolute">
    <origin rpy="0 0 0" xyz="0 0.035 0.059098"/>
    <parent link="xarm_gripper_base_link"/>
    <child link="left_outer_knuckle"/>
    <axis xyz="1 0 0"/>
    <limit effort="1.0" lower="0" upper="0.85" velocity="2"/>
    <dynamics damping="1.0" friction="0"/>
  </joint>
  <link name="left_finger">
    <inertial>
      <origin rpy="0 0 0" xyz="-2.4536E-14 -0.016413 0.029258"/>
      <mass value="0.048304"/>
      <inertia ixx="1.7493E-05" ixy="-4.2156E-19" ixz="6.9164E-18" iyy="1.7225E-05" iyz="4.6433E-06" izz="5.1466E-06"/>
    </inertial>
    <visual>
      <origin rpy="0 0 0" xyz="0 0 0"/>
      <geometry>
        <mesh filename="meshes/left_finger_combined.stl"/>
      </geometry>
      <material name="Silver">
        <color rgba="0.753 0.753 0.753 1.0"/>
      </material>
    </visual>
    <collision>
      <origin rpy="0 0 0" xyz="0 -0.0224 0.04"/>
      <geometry>
        <box size="0.032 0.0072 0.042"/>
      </geometry>
    </collision>
    <collision>
      <origin rpy="0 0 0" xyz="0 -0.0154 0.036"/>
      <geometry>
        <box size="0.032 0.0068 0.034"/>
      </geometry>
    </collision>
    <collision>
      <origin rpy="0.8 0 0" xyz="0 -0.008 0.008"/>
      <geometry>
        <box size="0.016 0.012 0.036"/>
      </geometry>
    </collision>
  </link>
  <joint name="left_finger_joint" type="revolute">
    <origin rpy="0 0 0" xyz="0 0.035465 0.042039"/>
    <parent link="left_outer_knuckle"/>
    <child link="left_finger"/>
    <axis xyz="-1 0 0"/>
    <limit effort="50" lower="0" upper="0.85" velocity="2"/>
    <!--<dynamics-->
    <!--  damping="1.0"-->
    <!--  friction="0" />-->
    <!--<mimic joint="drive_joint" multiplier="1" offset="0"/>-->
  </joint>
  <link name="left_inner_knuckle">
    <inertial>
      <origin rpy="0 0 0" xyz="1.86600784687907E-06 0.0220467847633621 0.0261334672830885"/>
      <mass value="0.0230125781256706"/>
      <inertia ixx="6.09490024271906E-06" ixy="6.06651326160071E-11" ixz="7.19102670500635E-11" iyy="6.01955084375188E-06" iyz="-2.75316812991721E-06" izz="5.07862004479903E-06"/>
    </inertial>
    <visual>
      <origin rpy="0 0 0" xyz="0 0 0"/>
      <geometry>
        <mesh filename="meshes/xarm_gripper/left_inner_knuckle.STL"/>
      </geometry>
      <material name="Silver">
        <color rgba="0.753 0.753 0.753 1.0"/>
      </material>
    </visual>
    <collision>
      <origin rpy="-0.7 0 0" xyz="0 0.016 0.02"/>
      <geometry>
        <box size="0.027 0.012 0.061"/>
      </geometry>
    </collision>
  </link>
  <joint name="left_inner_knuckle_joint" type="revolute">
    <origin rpy="0 0 0" xyz="0 0.02 0.074098"/>
    <parent link="xarm_gripper_base_link"/>
    <child link="left_inner_knuckle"/>
    <axis xyz="1 0 0"/>
    <limit effort="50" lower="0" upper="0.85" velocity="2"/>
    <!--<dynamics-->
    <!--  damping="1.0"-->
    <!--  friction="0" />-->
    <!--<mimic joint="drive_joint" multiplier="1" offset="0"/>-->
  </joint>
  <gazebo>
    <joint name="left_loop_joint" type="revolute">
      <parent>left_inner_knuckle</parent>
      <child>left_finger</child>
      <pose>0 -0.015 0.015 0 0 0</pose>
      <axis>
        <xyz>1 0 0</xyz>
        <use_parent_model_frame>false</use_parent_model_frame>
      </axis>
      <!--<physics>-->
      <!--  <ode>-->
      <!--    <implicit_spring_damper>1</implicit_spring_damper>-->
      <!--    <cfm_damping>0</cfm_damping>-->
      <!--    <limit>-->
      <!--      <cfm>1e-7</cfm>-->
      <!--      <erp>0.8</erp>-->
      <!--    </limit>-->
      <!--  </ode>-->
      <!--</physics>-->
    </joint>
  </gazebo>
  <link name="right_outer_knuckle">
    <inertial>
      <origin rpy="0 0 0" xyz="-3.1669E-14 -0.021559 0.015181"/>
      <mass value="0.033618"/>
      <inertia ixx="1.9111E-05" ixy="-1.8789E-17" ixz="1.0986E-17" iyy="6.6256E-06" iyz="7.3008E-06" izz="1.3185E-05"/>
    </inertial>
    <visual>
      <origin rpy="0 0 0" xyz="0 0 0"/>
      <geometry>
        <mesh filename="meshes/xarm_gripper/right_outer_knuckle.STL"/>
      </geometry>
      <material name="Silver">
        <color rgba="0.753 0.753 0.753 1.0"/>
      </material>
    </visual>
    <collision>
      <origin rpy="-0.48 0 0" xyz="0 -0.015 0.02"/>
      <geometry>
        <box size="0.012 0.069 0.033"/>
      </geometry>
    </collision>
  </link>
  <joint name="right_outer_knuckle_joint" type="revolute">
    <origin rpy="0 0 0" xyz="0 -0.035 0.059098"/>
    <parent link="xarm_gripper_base_link"/>
    <child link="right_outer_knuckle"/>
    <axis xyz="-1 0 0"/>
    <limit effort="50" lower="0" upper="0.85" velocity="2"/>
    <!--<dynamics-->
    <!--  damping="1.0"-->
    <!--  friction="0" />-->
    <!--<mimic joint="drive_joint" multiplier="1" offset="0"/>-->
  </joint>
  <link name="right_finger">
    <inertial>
      <origin rpy="0 0 0" xyz="2.5618E-14 0.016413 0.029258"/>
      <mass value="0.048304"/>
      <inertia ixx="1.7493E-05" ixy="-5.0014E-19" ixz="-7.5079E-18" iyy="1.7225E-05" iyz="-4.6435E-06" izz="5.1466E-06"/>
    </inertial>
    <visual>
      <origin rpy="0 0 0" xyz="0 0 0"/>
      <geometry>
        <mesh filename="meshes/right_finger_combined.stl"/>
      </geometry>
      <material name="Silver">
        <color rgba="0.753 0.753 0.753 1.0"/>
      </material>
    </visual>
    <collision>
      <origin rpy="0 0 0" xyz="0 0.0224 0.04"/>
      <geometry>
        <box size="0.032 0.0072 0.042"/>
      </geometry>
    </collision>
    <collision>
      <origin rpy="0 0 0" xyz="0 0.0154 0.036"/>
      <geometry>
        <box size="0.032 0.0068 0.034"/>
      </geometry>
    </collision>
    <collision>
      <origin rpy="-0.8 0 0" xyz="0 0.008 0.008"/>
      <geometry>
        <box size="0.016 0.012 0.036"/>
      </geometry>
    </collision>
  </link>
  <joint name="right_finger_joint" type="revolute">
    <origin rpy="0 0 0" xyz="0 -0.035465 0.042039"/>
    <parent link="right_outer_knuckle"/>
    <child link="right_finger"/>
    <axis xyz="1 0 0"/>
    <limit effort="50" lower="0" upper="0.85" velocity="2"/>
    <!--<dynamics-->
    <!--  damping="1.0"-->
    <!--  friction="0" />-->
    <!--<mimic joint="drive_joint" multiplier="1" offset="0"/>-->
  </joint>
  <link name="right_inner_knuckle">
    <inertial>
      <origin rpy="0 0 0" xyz="1.866E-06 -0.022047 0.026133"/>
      <mass value="0.023013"/>
      <inertia ixx="6.0949E-06" ixy="-6.0665E-11" ixz="7.191E-11" iyy="6.0197E-06" iyz="2.7531E-06" izz="5.0784E-06"/>
    </inertial>
    <visual>
      <origin rpy="0 0 0" xyz="0 0 0"/>
      <geometry>
        <mesh filename="meshes/xarm_gripper/right_inner_knuckle.STL"/>
      </geometry>
      <material name="Silver">
        <color rgba="0.753 0.753 0.753 1.0"/>
      </material>
    </visual>
    <collision>
      <origin rpy="0.7 0 0" xyz="0 -0.016 0.02"/>
      <geometry>
        <box size="0.027 0.012 0.061"/>
      </geometry>
    </collision>
  </link>
  <joint name="right_inner_knuckle_joint" type="revolute">
    <origin rpy="0 0 0" xyz="0 -0.02 0.074098"/>
    <parent link="xarm_gripper_base_link"/>
    <child link="right_inner_knuckle"/>
    <axis xyz="-1 0 0"/>
    <limit effort="0.5" lower="0" upper="0.85" velocity="2"/>
    <!--<dynamics-->
    <!--  damping="1.0"-->
    <!--  friction="0" />-->
    <!--<mimic joint="drive_joint" multiplier="1" offset="0"/>-->
  </joint>
  <gazebo>
    <joint name="right_loop_joint" type="revolute">
      <parent>right_inner_knuckle</parent>
      <child>right_finger</child>
      <pose>0 0.015 0.015 0 0 0</pose>
      <axis>
        <xyz>1 0 0</xyz>
        <use_parent_model_frame>false</use_parent_model_frame>
      </axis>
      <!--<physics>-->
      <!--  <ode>-->
      <!--    <implicit_spring_damper>1</implicit_spring_damper>-->
      <!--    <cfm_damping>0</cfm_damping>-->
      <!--    <limit>-->
      <!--      <cfm>1e-7</cfm>-->
      <!--      <erp>0.8</erp>-->
      <!--    </limit>-->
      <!--  </ode>-->
      <!--</physics>-->
    </joint>
  </gazebo>
  <link name="link_tcp"/>
  <joint name="joint_tcp" type="fixed">
    <origin rpy="0 0 0" xyz="0 0 0.172"/>
    <parent link="xarm_gripper_base_link"/>
    <child link="link_tcp"/>
  </joint>
  <transmission name="drive_joint_trans">
    <type>transmission_interface/SimpleTransmission</type>
    <joint name="drive_joint">
      <hardwareInterface>hardware_interface/PositionJointInterface</hardwareInterface>
    </joint>
    <actuator name="drive_joint_motor">
      <hardwareInterface>hardware_interface/PositionJointInterface</hardwareInterface>
      <mechanicalReduction>1</mechanicalReduction>
    </actuator>
  </transmission>
  <gazebo reference="xarm_gripper_base_link">
    <selfCollide>false</selfCollide>
  </gazebo>
  <gazebo reference="left_outer_knuckle">
    <selfCollide>false</selfCollide>
  </gazebo>
  <gazebo reference="left_finger">
    <kp>100000.0</kp>
    <kd>100.0</kd>
    <mu1>1e9</mu1>
    <mu2>1e9</mu2>
    <maxVel>1.0</maxVel>
    <minDepth>0.0001</minDepth>
    <maxContacts>16</maxContacts>
    <selfCollide>false</selfCollide>
    <dampingFactor>0</dampingFactor>
  </gazebo>
  <gazebo reference="left_inner_knuckle">
    <selfCollide>false</selfCollide>
  </gazebo>
  <gazebo reference="right_outer_knuckle">
    <selfCollide>false</selfCollide>
  </gazebo>
  <gazebo reference="right_finger">
    <kp>100000.0</kp>
    <kd>100.0</kd>
    <mu1>1e9</mu1>
    <mu2>1e9</mu2>
    <maxVel>1.0</maxVel>
    <minDepth>0.0001</minDepth>
    <maxContacts>16</maxContacts>
    <selfCollide>false</selfCollide>
    <dampingFactor>0</dampingFactor>
  </gazebo>
  <gazebo reference="right_inner_knuckle">
    <selfCollide>false</selfCollide>
  </gazebo>
  <gazebo reference="drive_joint">
    <implicitSpringDamper>1</implicitSpringDamper>
  </gazebo>
  <gazebo reference="left_finger_joint">
    <implicitSpringDamper>1</implicitSpringDamper>
  </gazebo>
  <gazebo reference="left_inner_knuckle_joint">
    <implicitSpringDamper>1</implicitSpringDamper>
  </gazebo>
  <gazebo reference="right_outer_knuckle_joint">
    <implicitSpringDamper>1</implicitSpringDamper>
  </gazebo>
  <gazebo reference="right_finger_joint">
    <implicitSpringDamper>1</implicitSpringDamper>
  </gazebo>
  <gazebo reference="right_inner_knuckle_joint">
    <implicitSpringDamper>1</implicitSpringDamper>
  </gazebo>
  <gazebo>
    <plugin filename="libgazebo_grasp_fix.so" name="gazebo_grasp_fix">
      <arm>
        <arm_name>xarm_gripper</arm_name>
        <palm_link>link7</palm_link>
        <gripper_link>left_inner_knuckle</gripper_link>
        <gripper_link>right_inner_knuckle</gripper_link>
        <!-- <gripper_link>${prefix}left_outer_knuckle</gripper_link>
          <gripper_link>${prefix}right_outer_knuckle</gripper_link> -->
        <gripper_link>left_finger</gripper_link>
        <gripper_link>right_finger</gripper_link>
      </arm>
      <forces_angle_tolerance>100</forces_angle_tolerance>
      <update_rate>10</update_rate>
      <grip_count_threshold>2</grip_count_threshold>
      <max_grip_count>3</max_grip_count>
      <release_tolerance>0.0198</release_tolerance>
      <disable_collisions_on_attach>false</disable_collisions_on_attach>
      <contact_topic>__default_topic__</contact_topic>
    </plugin>
  </gazebo>
  <gazebo>
    <!-- old version -->
    <plugin filename="libroboticsgroup_gazebo_mimic_joint_plugin.so" name="right_outer_knuckle_jointmimic_joint_plugin">
      <!-- new version -->
      <!-- <plugin name="${name_prefix}mimic_joint_plugin" filename="libroboticsgroup_upatras_gazebo_mimic_joint_plugin.so"> -->
      <joint>drive_joint</joint>
      <mimicJoint>right_outer_knuckle_joint</mimicJoint>
      <!-- if set to true, PID parameters from "/gazebo_ros_control/pid_gains/${mimic_joint}" are loaded -->
      <hasPID/>
      <multiplier>1.0</multiplier>
      <offset>0</offset>
      <sensitiveness>0.0</sensitiveness>
      <!-- if absolute difference between setpoint and process value is below this threshold, do nothing; 0.0 = disable [rad] -->
      <maxEffort>10.0</maxEffort>
    </plugin>
  </gazebo>
  <!-- camera body, with origin at bottom screw mount -->
  <joint name="hand_camera_joint" type="fixed">
    <origin rpy="0 -1.5707963267948966 3.141592653589793" xyz="0.0305 0 0.08015"/>
    <parent link="arm_link_eef"/>
    <child link="hand_camera_bottom_screw_frame"/>
  </joint>
  <link name="hand_camera_bottom_screw_frame"/>
  <joint name="hand_camera_link_joint" type="fixed">
    <origin rpy="0 0 0" xyz="0.010600000000000002 0.0175 0.0125"/>
    <parent link="hand_camera_bottom_screw_frame"/>
    <child link="hand_camera_link"/>
  </joint>
  <link name="hand_camera_link">
    <visual>
      <!-- the mesh origin is at front plate in between the two infrared camera axes -->
      <origin rpy="1.5707963267948966 0 1.5707963267948966" xyz="0.0043 -0.0175 0"/>
      <geometry>
        <mesh filename="meshes/d435.dae"/>
      </geometry>
    </visual>
    <collision>
      <origin rpy="0 0 0" xyz="0 -0.0175 0"/>
      <geometry>
        <box size="0.02505 0.09 0.025"/>
      </geometry>
    </collision>
    <inertial>
      <!-- The following are not reliable values, and should not be used for modeling -->
      <mass value="0.072"/>
      <origin xyz="0 0 0"/>
      <inertia ixx="0.003881243" ixy="0.0" ixz="0.0" iyy="0.000498940" iyz="0.0" izz="0.003879257"/>
    </inertial>
  </link>
  <!-- camera depth joints and links -->
  <joint name="hand_camera_depth_joint" type="fixed">
    <origin rpy="0 0 0" xyz="0 0 0"/>
    <parent link="hand_camera_link"/>
    <child link="hand_camera_depth_frame"/>
  </joint>
  <link name="hand_camera_depth_frame"/>
  <joint name="hand_camera_depth_optical_joint" type="fixed">
    <origin rpy="-1.5707963267948966 0 -1.5707963267948966" xyz="0 0 0"/>
    <parent link="hand_camera_depth_frame"/>
    <child link="hand_camera_depth_optical_frame"/>
  </joint>
  <link name="hand_camera_depth_optical_frame"/>
  <!-- camera left IR joints and links -->
  <joint name="hand_camera_infra1_joint" type="fixed">
    <origin rpy="0 0 0" xyz="0 0.0 0"/>
    <parent link="hand_camera_link"/>
    <child link="hand_camera_infra1_frame"/>
  </joint>
  <link name="hand_camera_infra1_frame"/>
  <joint name="hand_camera_infra1_optical_joint" type="fixed">
    <origin rpy="-1.5707963267948966 0 -1.5707963267948966" xyz="0 0 0"/>
    <parent link="hand_camera_infra1_frame"/>
    <child link="hand_camera_infra1_optical_frame"/>
  </joint>
  <link name="hand_camera_infra1_optical_frame"/>
  <!-- camera right IR joints and links -->
  <joint name="hand_camera_infra2_joint" type="fixed">
    <origin rpy="0 0 0" xyz="0 -0.05 0"/>
    <parent link="hand_camera_link"/>
    <child link="hand_camera_infra2_frame"/>
  </joint>
  <link name="hand_camera_infra2_frame"/>
  <joint name="hand_camera_infra2_optical_joint" type="fixed">
    <origin rpy="-1.5707963267948966 0 -1.5707963267948966" xyz="0 0 0"/>
    <parent link="hand_camera_infra2_frame"/>
    <child link="hand_camera_infra2_optical_frame"/>
  </joint>
  <link name="hand_camera_infra2_optical_frame"/>
  <!-- camera color joints and links -->
  <joint name="hand_camera_color_joint" type="fixed">
    <origin rpy="0 0 0" xyz="0 0.015 0"/>
    <parent link="hand_camera_link"/>
    <child link="hand_camera_color_frame"/>
  </joint>
  <link name="hand_camera_color_frame"/>
  <joint name="hand_camera_color_optical_joint" type="fixed">
    <origin rpy="-1.5707963267948966 0 -1.5707963267948966" xyz="0 0 0"/>
    <parent link="hand_camera_color_frame"/>
    <child link="hand_camera_color_optical_frame"/>
  </joint>
  <link name="hand_camera_color_optical_frame"/>
  <link name="hand_camera_accel_frame"/>
  <link name="hand_camera_accel_optical_frame"/>
  <link name="hand_camera_gyro_frame"/>
  <link name="hand_camera_gyro_optical_frame"/>
  <joint name="hand_camera_accel_joint" type="fixed">
    <origin rpy="0 0 0" xyz="-0.01174 -0.00552 0.0051"/>
    <parent link="hand_camera_link"/>
    <child link="hand_camera_accel_frame"/>
  </joint>
  <joint name="hand_camera_accel_optical_joint" type="fixed">
    <origin rpy="-1.5707963267948966 0 -1.5707963267948966" xyz="0 0 0"/>
    <parent link="hand_camera_accel_frame"/>
    <child link="hand_camera_accel_optical_frame"/>
  </joint>
  <joint name="hand_camera_gyro_joint" type="fixed">
    <origin rpy="0 0 0" xyz="-0.01174 -0.00552 0.0051"/>
    <parent link="hand_camera_link"/>
    <child link="hand_camera_gyro_frame"/>
  </joint>
  <joint name="hand_camera_gyro_optical_joint" type="fixed">
    <origin rpy="-1.5707963267948966 0 -1.5707963267948966" xyz="0 0 0"/>
    <parent link="hand_camera_gyro_frame"/>
    <child link="hand_camera_gyro_optical_frame"/>
  </joint>
  <!-- camera rgb joints and links -->
  <joint name="hand_camera_rgb_joint" type="fixed">
    <origin rpy="0 0 0" xyz="0 0 0"/>
    <parent link="hand_camera_color_frame"/>
    <child link="hand_camera_rgb_frame"/>
  </joint>
  <link name="hand_camera_rgb_frame"/>
  <joint name="hand_camera_rgb_optical_joint" type="fixed">
    <origin rpy="0 0 0" xyz="0 0 0"/>
    <parent link="hand_camera_color_optical_frame"/>
    <child link="hand_camera_rgb_optical_frame"/>
  </joint>
  <link name="hand_camera_rgb_optical_frame"/>
  <gazebo reference="hand_camera_depth_frame">
    <sensor name="camera" type="depth">
      <update_rate>15.0</update_rate>
      <camera>
        <horizontal_fov>1.5184364492350666</horizontal_fov>
        <vertical_fov>1.0122909661567112</vertical_fov>
        <image>
          <width>640</width>
          <height>480</height>
          <format>R8G8B8</format>
        </image>
        <clip>
          <near>0.05</near>
          <far>10</far>
        </clip>
      </camera>
      <plugin filename="libgazebo_ros_openni_kinect.so" name="depth_controller">
        <cameraName>hand_camera/depth</cameraName>
        <alwaysOn>true</alwaysOn>
        <updateRate>0</updateRate>
        <imageTopicName>gazebo/rgb/image_raw</imageTopicName>
        <cameraInfoTopicName>gazebo/rgb/camera_info</cameraInfoTopicName>
        <depthImageTopicName>image_raw</depthImageTopicName>
        <depthImageCameraInfoTopicName>camera_info</depthImageCameraInfoTopicName>
        <pointCloudTopicName>gazebo/points</pointCloudTopicName>
        <frameName>hand_camera_depth_optical_frame</frameName>
        <baseline>0.1</baseline>
        <distortion_k1>0.0</distortion_k1>
        <distortion_k2>0.0</distortion_k2>
        <distortion_k3>0.0</distortion_k3>
        <distortion_t1>0.0</distortion_t1>
        <distortion_t2>0.0</distortion_t2>
        <pointCloudCutoff>0.2</pointCloudCutoff>
      </plugin>
    </sensor>
  </gazebo>
  <gazebo reference="hand_camera_rgb_frame">
    <sensor name="camera" type="camera">
      <always_on>true</always_on>
      <update_rate>15.0</update_rate>
      <camera>
        <horizontal_fov>1.2042771838760873</horizontal_fov>
        <vertical_fov>0.7330382858376184</vertical_fov>
        <image>
          <format>B8G8R8</format>
          <width>640</width>
          <height>480</height>
        </image>
        <clip>
          <near>0.01</near>
          <far>8.0</far>
        </clip>
      </camera>
      <plugin filename="libgazebo_ros_camera.so" name="rgb_controller">
        <cameraName>hand_camera/rgb</cameraName>
        <alwaysOn>true</alwaysOn>
        <updateRate>0</updateRate>
        <imageTopicName>image_raw</imageTopicName>
        <cameraInfoTopicName>camera_info</cameraInfoTopicName>
        <frameName>hand_camera_rgb_optical_frame</frameName>
        <baseline>0.1</baseline>
        <distortion_k1>0.0</distortion_k1>
        <distortion_k2>0.0</distortion_k2>
        <distortion_k3>0.0</distortion_k3>
        <distortion_t1>0.0</distortion_t1>
        <distortion_t2>0.0</distortion_t2>
        <pointCloudCutoff>0.4</pointCloudCutoff>
      </plugin>
    </sensor>
  </gazebo>
  <joint name="left_finger_extension_joint" type="fixed">
    <origin rpy="0 0 0" xyz="0 -0.0224 0.055"/>
    <parent link="left_finger"/>
    <child link="left_finger_extension_link"/>
  </joint>
  <link name="left_finger_extension_link">
    <visual>
      <origin rpy="0 0 0" xyz="0 0 0"/>
      <geometry>
        <box size="0.032 0.0072 0.072"/>
      </geometry>
      <material name="White">
        <color rgba="1.0 1.0 1.0 1.0"/>
      </material>
    </visual>
    <collision>
      <origin rpy="0 0 0" xyz="0 0 0"/>
      <geometry>
        <box size="0.032 0.0072 0.072"/>
      </geometry>
    </collision>
    <inertial>
      <origin rpy="0 0 0" xyz="0.0 0 0"/>
      <mass value="0.01"/>
      <inertia ixx="1.5132000000000002e-06" ixy="0.0" ixz="0.0" iyy="4.673333333333334e-06" iyz="0.0" izz="3.246533333333333e-06"/>
    </inertial>
  </link>
  <gazebo reference="left_finger_extension_link">
    <kp>100000.0</kp>
    <kd>100.0</kd>
    <mu1>1e9</mu1>
    <mu2>1e9</mu2>
    <maxVel>1.0</maxVel>
    <minDepth>0.0001</minDepth>
    <maxContacts>16</maxContacts>
    <selfCollide>false</selfCollide>
    <dampingFactor>0</dampingFactor>
  </gazebo>
  <joint name="right_finger_extension_joint" type="fixed">
    <origin rpy="0 0 0" xyz="0 0.0224 0.055"/>
    <parent link="right_finger"/>
    <child link="right_finger_extension_link"/>
  </joint>
  <link name="right_finger_extension_link">
    <visual>
      <origin rpy="0 0 0" xyz="0 0 0"/>
      <geometry>
        <box size="0.032 0.0072 0.072"/>
      </geometry>
      <material name="White">
        <color rgba="1.0 1.0 1.0 1.0"/>
      </material>
    </visual>
    <collision>
      <origin rpy="0 0 0" xyz="0 0 0"/>
      <geometry>
        <box size="0.032 0.0072 0.072"/>
      </geometry>
    </collision>
    <inertial>
      <origin rpy="0 0 0" xyz="0.0 0 0"/>
      <mass value="0.01"/>
      <inertia ixx="1.5132000000000002e-06" ixy="0.0" ixz="0.0" iyy="4.673333333333334e-06" iyz="0.0" izz="3.246533333333333e-06"/>
    </inertial>
  </link>
  <gazebo reference="right_finger_extension_link">
    <kp>100000.0</kp>
    <kd>100.0</kd>
    <mu1>1e9</mu1>
    <mu2>1e9</mu2>
    <maxVel>1.0</maxVel>
    <minDepth>0.0001</minDepth>
    <maxContacts>16</maxContacts>
    <selfCollide>false</selfCollide>
    <dampingFactor>0</dampingFactor>
  </gazebo>
  <link name="link_tcp_extension"/>
  <joint name="joint_tcp_extension" type="fixed">
    <origin rpy="0 0 0" xyz="0 0 0.03"/>
    <parent link="link_tcp"/>
    <child link="link_tcp_extension"/>
  </joint>
  <joint name="head_pan_joint" type="revolute">
    <origin rpy="0 0 0" xyz="0.007 0.0 0.7331"/>
    <parent link="torso_link"/>
    <child link="head_pan_link"/>
    <axis xyz="0 0 1"/>
    <limit effort="5000.0" lower="-3.141592653589793" upper="3.141592653589793" velocity="100.0"/>
    <dynamics damping="0.01" friction="1.0"/>
  </joint>
  <transmission name="head_pan_transmission">
    <type>transmission_interface/SimpleTransmission</type>
    <joint name="head_pan_joint">
      <hardwareInterface>hardware_interface/PositionJointInterface</hardwareInterface>
    </joint>
    <actuator name="head_pan_motor">
      <mechanicalReduction>1</mechanicalReduction>
    </actuator>
  </transmission>
  <link name="head_pan_link">
    <visual>
      <origin rpy="0 0 0" xyz="0 0 0"/>
      <geometry>
        <mesh filename="meshes/head_pan.stl"/>
      </geometry>
      <material name="white">
        <color rgba="1 1 1 1"/>
      </material>
    </visual>
    <collision>
      <origin rpy="-1.5707963267948966 -1.5707963267948966 0.0" xyz="0.08250000141561031 -3.6739409996478224e-19 -0.0060000009834766405"/>
      <geometry>
        <box size="0.09200000017881398 0.23500000312924385 0.3140000104904175"/>
      </geometry>
    </collision>
    <inertial>
      <origin rpy="-1.5707963267948966 -1.5707963267948966 0.0" xyz="0.08250000141561031 -3.6739409996478224e-19 -0.0060000009834766405"/>
      <mass value="1.5"/>
      <inertia ixx="0.01922762600734086" ixy="0.0" ixz="0.0" iyy="0.013382500827610506" iyz="0.0" izz="0.0079611251879558"/>
    </inertial>
  </link>
  <gazebo reference="head_pan_link">
    <kp>10000.0</kp>
    <kd>0.0</kd>
    <mu1>0.0</mu1>
    <mu2>0.0</mu2>
    <maxVel>0.1</maxVel>
    <minDepth>0.0001</minDepth>
    <maxContacts>0</maxContacts>
    <selfCollide>false</selfCollide>
  </gazebo>
  <joint name="head_tilt_joint" type="revolute">
    <origin rpy="0 0 0" xyz="0.136 0.0 0.0"/>
    <parent link="head_pan_link"/>
    <child link="head_tilt_link"/>
    <axis xyz="0 1 0"/>
    <limit effort="5000.0" lower="-1.5707963267948966" upper="1.5707963267948966" velocity="100.0"/>
    <dynamics damping="0.01" friction="1.0"/>
  </joint>
  <transmission name="head_tilt_transmission">
    <type>transmission_interface/SimpleTransmission</type>
    <joint name="head_tilt_joint">
      <hardwareInterface>hardware_interface/PositionJointInterface</hardwareInterface>
    </joint>
    <actuator name="head_tilt_motor">
      <mechanicalReduction>1</mechanicalReduction>
    </actuator>
  </transmission>
  <link name="head_tilt_link">
    <visual>
      <origin rpy="0 0 0" xyz="0 0 0"/>
      <geometry>
        <mesh filename="meshes/head_tilt.stl"/>
      </geometry>
      <material name="white">
        <color rgba="1 1 1 1"/>
      </material>
    </visual>
    <collision>
      <origin rpy="1.59213780702364 1.5707963267948966 0.0" xyz="-0.0025854797636645967 0.0006421662044920561 0.03257735073566437"/>
      <geometry>
        <box size="0.15685470402240756 0.16187441211299564 0.25577065982136127"/>
      </geometry>
    </collision>
    <inertial>
      <origin rpy="1.59213780702364 1.5707963267948966 0.0" xyz="-0.0025854797636645967 0.0006421662044920561 0.03257735073566437"/>
      <mass value="1.5"/>
      <inertia ixx="0.011452744465297808" ixy="0.0" ixz="0.0" iyy="0.01125275357492645" iyz="0.0" izz="0.006350840433860628"/>
    </inertial>
  </link>
  <gazebo reference="head_tilt_link">
    <kp>10000.0</kp>
    <kd>0.0</kd>
    <mu1>0.0</mu1>
    <mu2>0.0</mu2>
    <maxVel>0.1</maxVel>
    <minDepth>0.0001</minDepth>
    <maxContacts>0</maxContacts>
    <selfCollide>false</selfCollide>
    <light name="led" type="spot">
      <pose frame="">0.07 0.084 0 0 -1.5707963267948966 0</pose>
      <diffuse>0.0 0.0 0.0 1</diffuse>
      <specular>0.1 0.1 0.1 1</specular>
      <direction>0 0 -1</direction>
      <attenuation>
        <range>20</range>
        <constant>0.1</constant>
        <linear>0.01</linear>
        <quadratic>0.001</quadratic>
      </attenuation>
      <cast_shadows>0</cast_shadows>
      <spot>
        <inner_angle>0.6</inner_angle>
        <outer_angle>1</outer_angle>
        <falloff>1</falloff>
      </spot>
    </light>
  </gazebo>
  <gazebo>
    <plugin filename="libsbgisen_light_plugin.so" name="led_control">
      <link>head_tilt_link</link>
      <namespace>/soar/light</namespace>
    </plugin>
  </gazebo>
  <joint name="head_camera_joint" type="fixed">
    <origin rpy="0 0 0" xyz="0.070 -0.0115 0.01365"/>
    <parent link="head_tilt_link"/>
    <child link="head_camera_base"/>
  </joint>
  <link name="head_camera_base">
    <visual>
      <origin xyz="-0.013 0. 0."/>
      <geometry>
        <box size="0.026 0.103 0.039"/>
      </geometry>
      <material name="grey">
        <color rgba="0.6 0.6 0.6 1"/>
      </material>
    </visual>
    <collision>
      <origin xyz="-0.013 0. 0."/>
      <geometry>
        <box size="0.026 0.103 0.039"/>
      </geometry>
    </collision>
  </link>
  <joint name="head_camera_base_to_body" type="fixed">
    <parent link="head_camera_base"/>
    <child link="head_camera_body"/>
    <origin rpy="0. 0. 0." xyz="-0.0757 0. 0.008"/>
  </joint>
  <link name="head_camera_body">
    <visual>
      <geometry>
        <box size="0.0994 0.0996 0.023"/>
      </geometry>
      <material name="white">
        <color rgba="0.9 0.9 0.9 1"/>
      </material>
    </visual>
    <collision>
      <geometry>
        <box size="0.0994 0.0996 0.023"/>
      </geometry>
    </collision>
  </link>
  <joint name="head_camera_base_to_visor" type="fixed">
    <parent link="head_camera_base"/>
    <child link="head_camera_visor"/>
    <origin rpy="0. 0. 0." xyz="0. 0. 0."/>
  </joint>
  <link name="head_camera_visor">
    <visual>
      <origin xyz="-0.0128 0. 0."/>
      <geometry>
        <box size="0.026 0.101 0.037"/>
      </geometry>
      <material name="black">
        <color rgba="0. 0. 0. 1"/>
      </material>
    </visual>
    <collision>
      <origin xyz="-0.0128 0. 0."/>
      <geometry>
        <box size="0.026 0.101 0.037"/>
      </geometry>
    </collision>
  </link>
  <joint name="head_camera_depth_optical_joint" type="fixed">
    <origin rpy="-1.6755063267948966 0 -1.5707963267948966" xyz="0 0 0.0018"/>
    <parent link="head_camera_base"/>
    <child link="head_camera_depth_optical_frame"/>
  </joint>
  <link name="head_camera_depth_optical_frame"/>
  <joint name="head_camera_depth_joint" type="fixed">
    <origin rpy="0 -1.5707963267948966 1.5707963267948966" xyz="0 0 0"/>
    <parent link="head_camera_depth_optical_frame"/>
    <child link="head_camera_depth_frame"/>
  </joint>
  <link name="head_camera_depth_frame"/>
  <joint name="head_camera_rgb_optical_joint" type="fixed">
    <origin rpy="0.10471 0 0" xyz="0.032 0.0018 -0.00634"/>
    <parent link="head_camera_depth_optical_frame"/>
    <child link="head_camera_rgb_optical_frame"/>
  </joint>
  <link name="head_camera_rgb_optical_frame"/>
  <joint name="head_camera_rgb_joint" type="fixed">
    <origin rpy="0 -1.5707963267948966 1.5707963267948966" xyz="0 0 0"/>
    <parent link="head_camera_rgb_optical_frame"/>
    <child link="head_camera_rgb_frame"/>
  </joint>
  <link name="head_camera_rgb_frame"/>
  <joint name="head_camera_imu_joint" type="fixed">
    <origin rpy="0 1.4660863267948965 1.5707963267948966" xyz="0.0 0.0 -0.05"/>
    <parent link="head_camera_depth_optical_frame"/>
    <child link="head_camera_imu_link"/>
  </joint>
  <link name="head_camera_imu_link"/>
  <gazebo reference="head_camera_visor">
    <material>Gazebo/Black</material>
  </gazebo>
  <gazebo reference="head_camera_base">
    <material>Gazebo/Grey</material>
  </gazebo>
  <gazebo reference="head_camera_depth_frame">
    <sensor name="camera" type="depth">
      <always_on>true</always_on>
      <update_rate>15.0</update_rate>
      <camera>
        <horizontal_fov>1.3089969389957472</horizontal_fov>
        <vertical_fov>1.1344640137963142</vertical_fov>
        <image>
          <format>B8G8R8</format>
          <width>640</width>
          <height>576</height>
        </image>
        <clip>
          <near>0.25</near>
          <far>3.0</far>
        </clip>
      </camera>
      <plugin filename="libgazebo_ros_openni_kinect.so" name="depth_controller">
        <cameraName>head_camera/depth</cameraName>
        <alwaysOn>true</alwaysOn>
        <updateRate>0</updateRate>
        <imageTopicName>gazebo/rgb/image_raw</imageTopicName>
        <cameraInfoTopicName>gazebo/rgb/camera_info</cameraInfoTopicName>
        <depthImageTopicName>image_raw</depthImageTopicName>
        <depthImageCameraInfoTopicName>camera_info</depthImageCameraInfoTopicName>
        <pointCloudTopicName>gazebo/points</pointCloudTopicName>
        <frameName>head_camera_depth_optical_frame</frameName>
        <baseline>0.1</baseline>
        <distortion_k1>0.0</distortion_k1>
        <distortion_k2>0.0</distortion_k2>
        <distortion_k3>0.0</distortion_k3>
        <distortion_t1>0.0</distortion_t1>
        <distortion_t2>0.0</distortion_t2>
        <pointCloudCutoff>0.25</pointCloudCutoff>
        <pointCloudCutoffMax>3.0</pointCloudCutoffMax>
      </plugin>
    </sensor>
  </gazebo>
  <gazebo reference="head_camera_rgb_frame">
    <sensor name="camera" type="camera">
      <always_on>true</always_on>
      <update_rate>15.0</update_rate>
      <camera>
        <horizontal_fov>1.5707963267948966</horizontal_fov>
        <vertical_fov>1.2967796342317868</vertical_fov>
        <image>
          <format>B8G8R8</format>
          <width>2048</width>
          <height>1536</height>
        </image>
        <clip>
          <near>0.01</near>
          <far>8.0</far>
        </clip>
      </camera>
      <plugin filename="libgazebo_ros_camera.so" name="rgb_controller">
        <cameraName>head_camera/rgb_no_resized</cameraName>
        <alwaysOn>true</alwaysOn>
        <updateRate>0</updateRate>
        <imageTopicName>image_raw</imageTopicName>
        <cameraInfoTopicName>camera_info</cameraInfoTopicName>
        <frameName>head_camera_rgb_optical_frame</frameName>
        <baseline>0.1</baseline>
        <distortion_k1>0.0</distortion_k1>
        <distortion_k2>0.0</distortion_k2>
        <distortion_k3>0.0</distortion_k3>
        <distortion_t1>0.0</distortion_t1>
        <distortion_t2>0.0</distortion_t2>
        <pointCloudCutoff>0.4</pointCloudCutoff>
      </plugin>
    </sensor>
  </gazebo>
  <joint name="zoom_camera_joint" type="fixed">
    <origin rpy="0 0 0" xyz="0.072 -0.089 0.000"/>
    <parent link="head_tilt_link"/>
    <child link="zoom_camera_rgb_frame"/>
  </joint>
  <link name="zoom_camera_rgb_frame">
    <visual>
      <origin rpy="0 1.5707963267948966 0" xyz="0. 0. 0.0005"/>
      <geometry>
        <cylinder length="0.007" radius="0.021"/>
      </geometry>
      <material name="black">
        <color rgba="0. 0. 0. 1"/>
      </material>
    </visual>
    <visual>
      <origin rpy="0 0 0" xyz="-0.04905 0. 0."/>
      <geometry>
        <box size="0.0921 0.05 0.0605"/>
      </geometry>
      <material name="black">
        <color rgba="0. 0. 0. 1"/>
      </material>
    </visual>
    <collision>
      <origin rpy="0 1.5707963267948966 0" xyz="0. 0. 0.0005"/>
      <geometry>
        <cylinder length="0.007" radius="0.021"/>
      </geometry>
    </collision>
    <collision>
      <origin rpy="0 0 0" xyz="-0.04905 0. 0."/>
      <geometry>
        <box size="0.0921 0.05 0.0605"/>
      </geometry>
    </collision>
  </link>
  <joint name="zoom_camera_rgb_optical_joint" type="fixed">
    <origin rpy="-1.5707963267948966 0 -1.5707963267948966" xyz="0. 0. 0."/>
    <parent link="zoom_camera_rgb_frame"/>
    <child link="zoom_camera_rgb_optical_frame"/>
  </joint>
  <link name="zoom_camera_rgb_optical_frame"/>
  <gazebo reference="zoom_camera_rgb_frame">
    <material>Gazebo/Black</material>
    <sensor name="camera" type="camera">
      <always_on>true</always_on>
      <update_rate>30.0</update_rate>
      <camera>
        <horizontal_fov>0.9470156521321232</horizontal_fov>
        <vertical_fov>0.7201228493728604</vertical_fov>
        <image>
          <format>B8G8R8</format>
          <width>1280</width>
          <height>720</height>
        </image>
        <clip>
          <near>0.01</near>
          <far>8.0</far>
        </clip>
      </camera>
      <plugin filename="libgazebo_ros_camera.so" name="rgb_controller">
        <cameraName>zoom_camera/rgb</cameraName>
        <alwaysOn>true</alwaysOn>
        <updateRate>0</updateRate>
        <imageTopicName>image_raw</imageTopicName>
        <cameraInfoTopicName>camera_info</cameraInfoTopicName>
        <frameName>zoom_camera_rgb_optical_frame</frameName>
        <baseline>0.1</baseline>
        <distortion_k1>0.0</distortion_k1>
        <distortion_k2>0.0</distortion_k2>
        <distortion_k3>0.0</distortion_k3>
        <distortion_t1>0.0</distortion_t1>
        <distortion_t2>0.0</distortion_t2>
        <pointCloudCutoff>0.4</pointCloudCutoff>
      </plugin>
    </sensor>
  </gazebo>
  <joint name="thermal_camera_joint" type="fixed">
    <origin rpy="0 0 0" xyz="0.04925 -0.0475 -0.02315"/>
    <parent link="head_tilt_link"/>
    <child link="thermal_camera_thermal_frame"/>
  </joint>
  <link name="thermal_camera_thermal_frame">
    <visual>
      <origin rpy="0 1.5707963267948966 0" xyz="-0.0055 0. -0.00275"/>
      <geometry>
        <cylinder length="0.011" radius="0.0105"/>
      </geometry>
      <material name="white">
        <color rgba="1 1 1 1"/>
      </material>
    </visual>
    <visual>
      <origin rpy="0 0 0" xyz="-0.01575 0.011725000000000001 0."/>
      <geometry>
        <box size="0.015 0.04445 0.025"/>
      </geometry>
      <material name="white">
        <color rgba="1 1 1 1"/>
      </material>
    </visual>
    <collision>
      <origin rpy="0 1.5707963267948966 0" xyz="-0.0055 0. 0."/>
      <geometry>
        <cylinder length="0.011" radius="0.0105"/>
      </geometry>
    </collision>
    <collision>
      <origin rpy="0 0 0" xyz="-0.0185 0.011725000000000001 0."/>
      <geometry>
        <box size="0.015 0.04445 0.025"/>
      </geometry>
    </collision>
  </link>
  <joint name="thermal_camera_thermal_optical_joint" type="fixed">
    <origin rpy="-1.5707963267948966 0 -1.5707963267948966" xyz="0. 0. 0."/>
    <parent link="thermal_camera_thermal_frame"/>
    <child link="thermal_camera_thermal_optical_frame"/>
  </joint>
  <link name="thermal_camera_thermal_optical_frame"/>
  <gazebo reference="thermal_camera_thermal_frame">
    <material>Gazebo/Black</material>
    <sensor name="camera" type="camera">
      <always_on>true</always_on>
      <update_rate>15.0</update_rate>
      <camera>
        <horizontal_fov>0.5585053606381855</horizontal_fov>
        <vertical_fov>0.5585053606381855</vertical_fov>
        <image>
          <format>B8G8R8</format>
          <width>320</width>
          <height>240</height>
        </image>
        <clip>
          <near>0.025</near>
          <far>50.0</far>
        </clip>
      </camera>
      <plugin filename="libgazebo_ros_thermal_camera.so" name="thermal_controller">
        <cameraName>thermal_camera/thermal</cameraName>
        <alwaysOn>true</alwaysOn>
        <updateRate>0</updateRate>
        <imageTopicName>image_raw</imageTopicName>
        <cameraInfoTopicName>camera_info</cameraInfoTopicName>
        <frameName>thermal_camera_thermal_optical_frame</frameName>
        <baseline>0.1</baseline>
        <distortion_k1>0.0</distortion_k1>
        <distortion_k2>0.0</distortion_k2>
        <distortion_k3>0.0</distortion_k3>
        <distortion_t1>0.0</distortion_t1>
        <distortion_t2>0.0</distortion_t2>
        <pointCloudCutoff>0.4</pointCloudCutoff>
      </plugin>
    </sensor>
  </gazebo>
  <joint name="light_joint" type="fixed">
    <origin rpy="0 0 0" xyz="0.065 0.077 0.000"/>
    <parent link="head_tilt_link"/>
    <child link="light_link"/>
  </joint>
  <link name="light_link">
    <visual>
      <origin rpy="0 0 0" xyz="0. 0. 0."/>
      <geometry>
        <sphere radius="0.0225"/>
      </geometry>
      <material name="white">
        <color rgba="1. 1. 1. 1"/>
      </material>
    </visual>
  </link>
  <joint name="mic_joint" type="fixed">
    <origin rpy="0 0 0" xyz="0.067 0.0245 -0.02315"/>
    <parent link="head_tilt_link"/>
    <child link="mic_link"/>
  </joint>
  <link name="mic_link"/>
</robot>

